<?xml version="1.0" ?>
<!-- =================================================================================== -->
<!-- |    This document was autogenerated by xacro from urdf\with_craw.xacro           | -->
<!-- |    EDITING THIS FILE BY HAND IS NOT RECOMMENDED                                 | -->
<!-- =================================================================================== -->
<robot xmlns:xacro="http://www.ros.org/wiki/xacro" name="with_craw">
  <material name="silver">
    <color rgba="0.700 0.700 0.700 1.000"/>
  </material>
  <transmission name="Revolute 2_tran">
    <type>transmission_interface/SimpleTransmission</type>
    <joint name="Revolute 2">
      <hardwareInterface>hardware_interface/EffortJointInterface</hardwareInterface>
    </joint>
    <actuator name="Revolute 2_actr">
      <hardwareInterface>hardware_interface/EffortJointInterface</hardwareInterface>
      <mechanicalReduction>1</mechanicalReduction>
    </actuator>
  </transmission>
  <transmission name="Revolute 3_tran">
    <type>transmission_interface/SimpleTransmission</type>
    <joint name="Revolute 3">
      <hardwareInterface>hardware_interface/EffortJointInterface</hardwareInterface>
    </joint>
    <actuator name="Revolute 3_actr">
      <hardwareInterface>hardware_interface/EffortJointInterface</hardwareInterface>
      <mechanicalReduction>1</mechanicalReduction>
    </actuator>
  </transmission>
  <transmission name="Revolute 8_tran">
    <type>transmission_interface/SimpleTransmission</type>
    <joint name="Revolute 8">
      <hardwareInterface>hardware_interface/EffortJointInterface</hardwareInterface>
    </joint>
    <actuator name="Revolute 8_actr">
      <hardwareInterface>hardware_interface/EffortJointInterface</hardwareInterface>
      <mechanicalReduction>1</mechanicalReduction>
    </actuator>
  </transmission>
  <transmission name="Revolute 11_tran">
    <type>transmission_interface/SimpleTransmission</type>
    <joint name="Revolute 11">
      <hardwareInterface>hardware_interface/EffortJointInterface</hardwareInterface>
    </joint>
    <actuator name="Revolute 11_actr">
      <hardwareInterface>hardware_interface/EffortJointInterface</hardwareInterface>
      <mechanicalReduction>1</mechanicalReduction>
    </actuator>
  </transmission>
  <transmission name="Revolute 12_tran">
    <type>transmission_interface/SimpleTransmission</type>
    <joint name="Revolute 12">
      <hardwareInterface>hardware_interface/EffortJointInterface</hardwareInterface>
    </joint>
    <actuator name="Revolute 12_actr">
      <hardwareInterface>hardware_interface/EffortJointInterface</hardwareInterface>
      <mechanicalReduction>1</mechanicalReduction>
    </actuator>
  </transmission>
  <transmission name="Revolute 13_tran">
    <type>transmission_interface/SimpleTransmission</type>
    <joint name="Revolute 13">
      <hardwareInterface>hardware_interface/EffortJointInterface</hardwareInterface>
    </joint>
    <actuator name="Revolute 13_actr">
      <hardwareInterface>hardware_interface/EffortJointInterface</hardwareInterface>
      <mechanicalReduction>1</mechanicalReduction>
    </actuator>
  </transmission>
  <transmission name="Slider 19_tran">
    <type>transmission_interface/SimpleTransmission</type>
    <joint name="Slider 19">
      <hardwareInterface>hardware_interface/EffortJointInterface</hardwareInterface>
    </joint>
    <actuator name="Slider 19_actr">
      <hardwareInterface>hardware_interface/EffortJointInterface</hardwareInterface>
      <mechanicalReduction>1</mechanicalReduction>
    </actuator>
  </transmission>
  <transmission name="Slider 20_tran">
    <type>transmission_interface/SimpleTransmission</type>
    <joint name="Slider 20">
      <hardwareInterface>hardware_interface/EffortJointInterface</hardwareInterface>
    </joint>
    <actuator name="Slider 20_actr">
      <hardwareInterface>hardware_interface/EffortJointInterface</hardwareInterface>
      <mechanicalReduction>1</mechanicalReduction>
    </actuator>
  </transmission>
  <gazebo>
    <plugin name="control" filename="libgazebo_ros_control.so"/>
  </gazebo>
  <gazebo reference="base_link">
    <material>Gazebo/Silver</material>
    <mu1>0.2</mu1>
    <mu2>0.2</mu2>
    <selfCollide>true</selfCollide>
    <gravity>true</gravity>
  </gazebo>
  <gazebo reference="joint251_1">
    <material>Gazebo/Silver</material>
    <mu1>0.2</mu1>
    <mu2>0.2</mu2>
    <selfCollide>true</selfCollide>
  </gazebo>
  <gazebo reference="joint251_2">
    <material>Gazebo/Silver</material>
    <mu1>0.2</mu1>
    <mu2>0.2</mu2>
    <selfCollide>true</selfCollide>
  </gazebo>
  <gazebo reference="larm_1">
    <material>Gazebo/Silver</material>
    <mu1>0.2</mu1>
    <mu2>0.2</mu2>
    <selfCollide>true</selfCollide>
  </gazebo>
  <gazebo reference="25joint_1">
    <material>Gazebo/Silver</material>
    <mu1>0.2</mu1>
    <mu2>0.2</mu2>
    <selfCollide>true</selfCollide>
  </gazebo>
  <gazebo reference="trans_1">
    <material>Gazebo/Silver</material>
    <mu1>0.2</mu1>
    <mu2>0.2</mu2>
    <selfCollide>true</selfCollide>
  </gazebo>
  <gazebo reference="uarm_1">
    <material>Gazebo/Silver</material>
    <mu1>0.2</mu1>
    <mu2>0.2</mu2>
    <selfCollide>true</selfCollide>
  </gazebo>
  <gazebo reference="joint14_1">
    <material>Gazebo/Silver</material>
    <mu1>0.2</mu1>
    <mu2>0.2</mu2>
    <selfCollide>true</selfCollide>
  </gazebo>
  <gazebo reference="joint142_1">
    <material>Gazebo/Silver</material>
    <mu1>0.2</mu1>
    <mu2>0.2</mu2>
    <selfCollide>true</selfCollide>
  </gazebo>
  <gazebo reference="joint143_1">
    <material>Gazebo/Silver</material>
    <mu1>0.2</mu1>
    <mu2>0.2</mu2>
    <selfCollide>true</selfCollide>
  </gazebo>
  <gazebo reference="flange_1">
    <material>Gazebo/Silver</material>
    <mu1>0.2</mu1>
    <mu2>0.2</mu2>
    <selfCollide>true</selfCollide>
  </gazebo>
  <gazebo reference="board_1">
    <material>Gazebo/Silver</material>
    <mu1>0.2</mu1>
    <mu2>0.2</mu2>
    <selfCollide>true</selfCollide>
  </gazebo>
  <gazebo reference="craw_1">
    <material>Gazebo/Silver</material>
    <mu1>0.2</mu1>
    <mu2>0.2</mu2>
    <selfCollide>true</selfCollide>
  </gazebo>
  <gazebo reference="cralwer_deap_1">
    <material>Gazebo/Silver</material>
    <mu1>0.2</mu1>
    <mu2>0.2</mu2>
    <selfCollide>true</selfCollide>
  </gazebo>
  <gazebo reference="crawler_deap12_1">
    <material>Gazebo/Silver</material>
    <mu1>0.2</mu1>
    <mu2>0.2</mu2>
    <selfCollide>true</selfCollide>
  </gazebo>
  <link name="base_link">
    <inertial>
      <origin xyz="9.954103263505598e-09 -0.0015502821747043515 0.1223159317118989" rpy="0 0 0"/>
      <mass value="7.80323249079454"/>
      <inertia ixx="0.012989" iyy="0.01227" izz="0.018229" ixy="0.0" iyz="1.6e-05" ixz="-0.0"/>
    </inertial>
    <visual>
      <origin xyz="0 0 0" rpy="0 0 0"/>
      <geometry>
        <mesh filename="package://robot_description/meshes/base_link.stl" scale="0.001 0.001 0.001"/>
      </geometry>
      <material name="silver"/>
    </visual>
    <collision>
      <origin xyz="0 0 0" rpy="0 0 0"/>
      <geometry>
        <mesh filename="package://robot_description/meshes/base_link.stl" scale="0.001 0.001 0.001"/>
      </geometry>
    </collision>
  </link>
  <link name="joint251_1">
    <inertial>
      <origin xyz="0.007407255316287612 9.443880300205346e-09 0.07775349829951264" rpy="0 0 0"/>
      <mass value="15.540708623156787"/>
      <inertia ixx="0.041918" iyy="0.045424" izz="0.033427" ixy="-0.0" iyz="0.0" ixz="0.000116"/>
    </inertial>
    <visual>
      <origin xyz="0.0 -0.0 -0.16" rpy="0 0 0"/>
      <geometry>
        <mesh filename="package://robot_description/meshes/joint251_1.stl" scale="0.001 0.001 0.001"/>
      </geometry>
      <material name="silver"/>
    </visual>
    <collision>
      <origin xyz="0.0 -0.0 -0.16" rpy="0 0 0"/>
      <geometry>
        <mesh filename="package://robot_description/meshes/joint251_1.stl" scale="0.001 0.001 0.001"/>
      </geometry>
    </collision>
  </link>
  <link name="joint251_2">
    <inertial>
      <origin xyz="0.07775349829951257 -9.443880299997178e-09 0.0074073567206075774" rpy="0 0 0"/>
      <mass value="15.540708623156787"/>
      <inertia ixx="0.033427" iyy="0.045424" izz="0.041918" ixy="-0.0" iyz="0.0" ixz="0.000116"/>
    </inertial>
    <visual>
      <origin xyz="-0.071 -0.0 -0.236501" rpy="0 0 0"/>
      <geometry>
        <mesh filename="package://robot_description/meshes/joint251_2.stl" scale="0.001 0.001 0.001"/>
      </geometry>
      <material name="silver"/>
    </visual>
    <collision>
      <origin xyz="-0.071 -0.0 -0.236501" rpy="0 0 0"/>
      <geometry>
        <mesh filename="package://robot_description/meshes/joint251_2.stl" scale="0.001 0.001 0.001"/>
      </geometry>
    </collision>
  </link>
  <link name="larm_1">
    <inertial>
      <origin xyz="-0.147501 0.0 -0.307501" rpy="0 0 0"/>
      <mass value="0.0"/>
      <inertia ixx="0.0" iyy="0.0" izz="0.0" ixy="0.0" iyz="0.0" ixz="0.0"/>
    </inertial>
    <visual>
      <origin xyz="-0.147501 0.0 -0.307501" rpy="0 0 0"/>
      <geometry>
        <mesh filename="package://robot_description/meshes/larm_1.stl" scale="0.001 0.001 0.001"/>
      </geometry>
      <material name="silver"/>
    </visual>
    <collision>
      <origin xyz="-0.147501 0.0 -0.307501" rpy="0 0 0"/>
      <geometry>
        <mesh filename="package://robot_description/meshes/larm_1.stl" scale="0.001 0.001 0.001"/>
      </geometry>
    </collision>
  </link>
  <link name="25joint_1">
    <inertial>
      <origin xyz="0.0012524982995125444 9.443880291323559e-09 0.06359284608803206" rpy="0 0 0"/>
      <mass value="15.540708623156787"/>
      <inertia ixx="0.033427" iyy="0.045424" izz="0.041918" ixy="0.0" iyz="0.0" ixz="-0.000116"/>
    </inertial>
    <visual>
      <origin xyz="-0.147501 0.0 -0.574501" rpy="0 0 0"/>
      <geometry>
        <mesh filename="package://robot_description/meshes/25joint_1.stl" scale="0.001 0.001 0.001"/>
      </geometry>
      <material name="silver"/>
    </visual>
    <collision>
      <origin xyz="-0.147501 0.0 -0.574501" rpy="0 0 0"/>
      <geometry>
        <mesh filename="package://robot_description/meshes/25joint_1.stl" scale="0.001 0.001 0.001"/>
      </geometry>
    </collision>
  </link>
  <link name="trans_1">
    <inertial>
      <origin xyz="-0.04834807020879976 -2.133823642225252e-09 0.0023734187016306585" rpy="0 0 0"/>
      <mass value="9.76158423031047"/>
      <inertia ixx="0.019423" iyy="0.01826" izz="0.017278" ixy="0.0" iyz="-0.0" ixz="-8.1e-05"/>
    </inertial>
    <visual>
      <origin xyz="-0.071 0.0 -0.645501" rpy="0 0 0"/>
      <geometry>
        <mesh filename="package://robot_description/meshes/trans_1.stl" scale="0.001 0.001 0.001"/>
      </geometry>
      <material name="silver"/>
    </visual>
    <collision>
      <origin xyz="-0.071 0.0 -0.645501" rpy="0 0 0"/>
      <geometry>
        <mesh filename="package://robot_description/meshes/trans_1.stl" scale="0.001 0.001 0.001"/>
      </geometry>
    </collision>
  </link>
  <link name="uarm_1">
    <inertial>
      <origin xyz="-0.026 0.0 -0.710601" rpy="0 0 0"/>
      <mass value="0.0"/>
      <inertia ixx="0.0" iyy="0.0" izz="0.0" ixy="0.0" iyz="0.0" ixz="0.0"/>
    </inertial>
    <visual>
      <origin xyz="-0.026 -0.0 -0.710601" rpy="0 0 0"/>
      <geometry>
        <mesh filename="package://robot_description/meshes/uarm_1.stl" scale="0.001 0.001 0.001"/>
      </geometry>
      <material name="silver"/>
    </visual>
    <collision>
      <origin xyz="-0.026 -0.0 -0.710601" rpy="0 0 0"/>
      <geometry>
        <mesh filename="package://robot_description/meshes/uarm_1.stl" scale="0.001 0.001 0.001"/>
      </geometry>
    </collision>
  </link>
  <link name="joint14_1">
    <inertial>
      <origin xyz="-0.0013163614832422087 6.989364011106081e-09 0.044489875500995035" rpy="0 0 0"/>
      <mass value="6.462489586316137"/>
      <inertia ixx="0.006667" iyy="0.012155" izz="0.011497" ixy="-0.0" iyz="0.0" ixz="4.7e-05"/>
    </inertial>
    <visual>
      <origin xyz="-0.026 -0.0 -0.947601" rpy="0 0 0"/>
      <geometry>
        <mesh filename="package://robot_description/meshes/joint14_1.stl" scale="0.001 0.001 0.001"/>
      </geometry>
      <material name="silver"/>
    </visual>
    <collision>
      <origin xyz="-0.026 -0.0 -0.947601" rpy="0 0 0"/>
      <geometry>
        <mesh filename="package://robot_description/meshes/joint14_1.stl" scale="0.001 0.001 0.001"/>
      </geometry>
    </collision>
  </link>
  <link name="joint142_1">
    <inertial>
      <origin xyz="0.04448977409667382 -6.989367042213665e-09 -0.0013162600789008438" rpy="0 0 0"/>
      <mass value="6.462489586316137"/>
      <inertia ixx="0.011497" iyy="0.012155" izz="0.006667" ixy="-0.0" iyz="0.0" ixz="4.7e-05"/>
    </inertial>
    <visual>
      <origin xyz="-0.094 0.0 -0.996601" rpy="0 0 0"/>
      <geometry>
        <mesh filename="package://robot_description/meshes/joint142_1.stl" scale="0.001 0.001 0.001"/>
      </geometry>
      <material name="silver"/>
    </visual>
    <collision>
      <origin xyz="-0.094 0.0 -0.996601" rpy="0 0 0"/>
      <geometry>
        <mesh filename="package://robot_description/meshes/joint142_1.stl" scale="0.001 0.001 0.001"/>
      </geometry>
    </collision>
  </link>
  <link name="joint143_1">
    <inertial>
      <origin xyz="0.001316361483200329 -6.989370806564921e-09 0.04448987550101702" rpy="0 0 0"/>
      <mass value="6.4624895863161385"/>
      <inertia ixx="0.006667" iyy="0.012155" izz="0.011497" ixy="-0.0" iyz="-0.0" ixz="-4.7e-05"/>
    </inertial>
    <visual>
      <origin xyz="-0.143 0.0 -1.064601" rpy="0 0 0"/>
      <geometry>
        <mesh filename="package://robot_description/meshes/joint143_1.stl" scale="0.001 0.001 0.001"/>
      </geometry>
      <material name="silver"/>
    </visual>
    <collision>
      <origin xyz="-0.143 0.0 -1.064601" rpy="0 0 0"/>
      <geometry>
        <mesh filename="package://robot_description/meshes/joint143_1.stl" scale="0.001 0.001 0.001"/>
      </geometry>
    </collision>
  </link>
  <link name="flange_1">
    <inertial>
      <origin xyz="-0.012106817573210152 -4.741664094557042e-15 -2.655884810787157e-05" rpy="0 0 0"/>
      <mass value="1.24878893227101"/>
      <inertia ixx="0.001091" iyy="0.000662" izz="0.000662" ixy="0.0" iyz="-0.0" ixz="-1e-06"/>
    </inertial>
    <visual>
      <origin xyz="-0.075 0.0 -1.113601" rpy="0 0 0"/>
      <geometry>
        <mesh filename="package://robot_description/meshes/flange_1.stl" scale="0.001 0.001 0.001"/>
      </geometry>
      <material name="silver"/>
    </visual>
    <collision>
      <origin xyz="-0.075 0.0 -1.113601" rpy="0 0 0"/>
      <geometry>
        <mesh filename="package://robot_description/meshes/flange_1.stl" scale="0.001 0.001 0.001"/>
      </geometry>
    </collision>
  </link>
  <link name="board_1">
    <inertial>
      <origin xyz="-0.002504966782930447 -6.7501559897209515e-15 0.027553796832819" rpy="0 0 0"/>
      <mass value="0.37239652270283546"/>
      <inertia ixx="0.000605" iyy="0.000357" izz="0.00025" ixy="-0.0" iyz="0.0" ixz="0.0"/>
    </inertial>
    <visual>
      <origin xyz="-0.0435 0.0 -1.113601" rpy="0 0 0"/>
      <geometry>
        <mesh filename="package://robot_description/meshes/board_1.stl" scale="0.001 0.001 0.001"/>
      </geometry>
      <material name="silver"/>
    </visual>
    <collision>
      <origin xyz="-0.0435 0.0 -1.113601" rpy="0 0 0"/>
      <geometry>
        <mesh filename="package://robot_description/meshes/board_1.stl" scale="0.001 0.001 0.001"/>
      </geometry>
    </collision>
  </link>
  <link name="craw_1">
    <inertial>
      <origin xyz="-0.028002904899663093 -0.03408764646558082 -0.011999898595712377" rpy="0 0 0"/>
      <mass value="2.0529823308563824"/>
      <inertia ixx="0.003426" iyy="0.000782" izz="0.003843" ixy="8.9e-05" iyz="-0.0" ixz="-0.0"/>
    </inertial>
    <visual>
      <origin xyz="-0.0375 -0.0345 -1.173101" rpy="0 0 0"/>
      <geometry>
        <mesh filename="package://robot_description/meshes/craw_1.stl" scale="0.001 0.001 0.001"/>
      </geometry>
      <material name="silver"/>
    </visual>
    <collision>
      <origin xyz="-0.0375 -0.0345 -1.173101" rpy="0 0 0"/>
      <geometry>
        <mesh filename="package://robot_description/meshes/craw_1.stl" scale="0.001 0.001 0.001"/>
      </geometry>
    </collision>
  </link>
  <link name="cralwer_deap_1">
    <inertial>
      <origin xyz="-0.021162686578159576 0.03040895522968348 -0.008749898604404116" rpy="0 0 0"/>
      <mass value="0.23667750006845437"/>
      <inertia ixx="0.000223" iyy="0.000135" izz="0.000236" ixy="7.1e-05" iyz="0.0" ixz="-0.0"/>
    </inertial>
    <visual>
      <origin xyz="0.0165 -0.0255 -1.169851" rpy="0 0 0"/>
      <geometry>
        <mesh filename="package://robot_description/meshes/cralwer_deap_1.stl" scale="0.001 0.001 0.001"/>
      </geometry>
      <material name="silver"/>
    </visual>
    <collision>
      <origin xyz="0.0165 -0.0255 -1.169851" rpy="0 0 0"/>
      <geometry>
        <mesh filename="package://robot_description/meshes/cralwer_deap_1.stl" scale="0.001 0.001 0.001"/>
      </geometry>
    </collision>
  </link>
  <link name="crawler_deap12_1">
    <inertial>
      <origin xyz="-0.021162686578159715 -0.03040895522969733 -0.008749898587053773" rpy="0 0 0"/>
      <mass value="0.236677500068455"/>
      <inertia ixx="0.000223" iyy="0.000135" izz="0.000236" ixy="-7.1e-05" iyz="0.0" ixz="0.0"/>
    </inertial>
    <visual>
      <origin xyz="0.0165 0.0285 -1.169851" rpy="0 0 0"/>
      <geometry>
        <mesh filename="package://robot_description/meshes/crawler_deap12_1.stl" scale="0.001 0.001 0.001"/>
      </geometry>
      <material name="silver"/>
    </visual>
    <collision>
      <origin xyz="0.0165 0.0285 -1.169851" rpy="0 0 0"/>
      <geometry>
        <mesh filename="package://robot_description/meshes/crawler_deap12_1.stl" scale="0.001 0.001 0.001"/>
      </geometry>
    </collision>
  </link>
  <joint name="Revolute 2" type="continuous">
    <origin xyz="0.0 0.0 0.16" rpy="0 0 0"/>
    <parent link="base_link"/>
    <child link="joint251_1"/>
    <axis xyz="0.0 0.0 1.0"/>
  </joint>
  <joint name="Revolute 3" type="continuous">
    <origin xyz="0.071 0.0 0.076501" rpy="0 0 0"/>
    <parent link="joint251_1"/>
    <child link="joint251_2"/>
    <axis xyz="1.0 0.0 0.0"/>
  </joint>
  <joint name="Rigid 4" type="fixed">
    <origin xyz="0.076501 -0.0 0.071" rpy="0 0 0"/>
    <parent link="joint251_2"/>
    <child link="larm_1"/>
  </joint>
  <joint name="Rigid 6" type="fixed">
    <origin xyz="0.0 0.0 0.267" rpy="0 0 0"/>
    <parent link="larm_1"/>
    <child link="25joint_1"/>
  </joint>
  <joint name="Revolute 8" type="continuous">
    <origin xyz="-0.076501 0.0 0.071" rpy="0 0 0"/>
    <parent link="25joint_1"/>
    <child link="trans_1"/>
    <axis xyz="-1.0 0.0 0.0"/>
  </joint>
  <joint name="Rigid 9" type="fixed">
    <origin xyz="-0.045 0.0 0.0651" rpy="0 0 0"/>
    <parent link="trans_1"/>
    <child link="uarm_1"/>
  </joint>
  <joint name="Rigid 10" type="fixed">
    <origin xyz="0.0 0.0 0.237" rpy="0 0 0"/>
    <parent link="uarm_1"/>
    <child link="joint14_1"/>
  </joint>
  <joint name="Revolute 11" type="continuous">
    <origin xyz="0.068 -0.0 0.049" rpy="0 0 0"/>
    <parent link="joint14_1"/>
    <child link="joint142_1"/>
    <axis xyz="1.0 -0.0 0.0"/>
  </joint>
  <joint name="Revolute 12" type="continuous">
    <origin xyz="0.049 0.0 0.068" rpy="0 0 0"/>
    <parent link="joint142_1"/>
    <child link="joint143_1"/>
    <axis xyz="-0.0 -0.0 1.0"/>
  </joint>
  <joint name="Revolute 13" type="continuous">
    <origin xyz="-0.068 0.0 0.049" rpy="0 0 0"/>
    <parent link="joint143_1"/>
    <child link="flange_1"/>
    <axis xyz="-1.0 0.0 -0.0"/>
  </joint>
  <joint name="Rigid 16" type="fixed">
    <origin xyz="-0.0315 0.0 0.0" rpy="0 0 0"/>
    <parent link="flange_1"/>
    <child link="board_1"/>
  </joint>
  <joint name="Rigid 17" type="fixed">
    <origin xyz="-0.006 0.0345 0.0595" rpy="0 0 0"/>
    <parent link="board_1"/>
    <child link="craw_1"/>
  </joint>
  <joint name="Slider 19" type="prismatic">
    <origin xyz="-0.054 -0.009 -0.00325" rpy="0 0 0"/>
    <parent link="craw_1"/>
    <child link="cralwer_deap_1"/>
    <axis xyz="-0.0 1.0 0.0"/>
    <limit upper="0.01" lower="-0.01" effort="100" velocity="100"/>
  </joint>
  <joint name="Slider 20" type="prismatic">
    <origin xyz="-0.054 -0.063 -0.00325" rpy="0 0 0"/>
    <parent link="craw_1"/>
    <child link="crawler_deap12_1"/>
    <axis xyz="-0.0 1.0 0.0"/>
    <limit upper="0.01" lower="-0.01" effort="100" velocity="100"/>
  </joint>
</robot>
